[2024-05-05T02:08:25.633+0000] {local_task_job_runner.py:120} INFO - ::group::Pre task execution logs
[2024-05-05T02:08:25.657+0000] {taskinstance.py:2073} INFO - Dependencies all met for dep_context=non-requeueable deps ti=<TaskInstance: mysql_table_dump.mysql_table_dump_task scheduled__2024-05-04T00:00:00+00:00 [queued]>
[2024-05-05T02:08:25.666+0000] {taskinstance.py:2073} INFO - Dependencies all met for dep_context=requeueable deps ti=<TaskInstance: mysql_table_dump.mysql_table_dump_task scheduled__2024-05-04T00:00:00+00:00 [queued]>
[2024-05-05T02:08:25.666+0000] {taskinstance.py:2303} INFO - Starting attempt 1 of 2
[2024-05-05T02:08:25.730+0000] {taskinstance.py:2327} INFO - Executing <Task(BashOperator): mysql_table_dump_task> on 2024-05-04 00:00:00+00:00
[2024-05-05T02:08:25.740+0000] {warnings.py:110} WARNING - /home/***/.local/lib/python3.12/site-packages/***/task/task_runner/standard_task_runner.py:61: DeprecationWarning: This process (pid=55) is multi-threaded, use of fork() may lead to deadlocks in the child.
  pid = os.fork()

[2024-05-05T02:08:25.742+0000] {standard_task_runner.py:63} INFO - Started process 56 to run task
[2024-05-05T02:08:25.742+0000] {standard_task_runner.py:90} INFO - Running: ['***', 'tasks', 'run', 'mysql_table_dump', 'mysql_table_dump_task', 'scheduled__2024-05-04T00:00:00+00:00', '--job-id', '5', '--raw', '--subdir', 'DAGS_FOLDER/dump_load_dag.py', '--cfg-path', '/tmp/tmp0hqzp89t']
[2024-05-05T02:08:25.745+0000] {standard_task_runner.py:91} INFO - Job 5: Subtask mysql_table_dump_task
[2024-05-05T02:08:25.815+0000] {task_command.py:426} INFO - Running <TaskInstance: mysql_table_dump.mysql_table_dump_task scheduled__2024-05-04T00:00:00+00:00 [running]> on host 284b5f341ead
[2024-05-05T02:08:25.914+0000] {taskinstance.py:2644} INFO - Exporting env vars: AIRFLOW_CTX_DAG_OWNER='***' AIRFLOW_CTX_DAG_ID='mysql_table_dump' AIRFLOW_CTX_TASK_ID='mysql_table_dump_task' AIRFLOW_CTX_EXECUTION_DATE='2024-05-04T00:00:00+00:00' AIRFLOW_CTX_TRY_NUMBER='1' AIRFLOW_CTX_DAG_RUN_ID='scheduled__2024-05-04T00:00:00+00:00'
[2024-05-05T02:08:25.915+0000] {taskinstance.py:430} INFO - ::endgroup::
[2024-05-05T02:08:25.943+0000] {subprocess.py:63} INFO - Tmp dir root location: /tmp
[2024-05-05T02:08:25.944+0000] {subprocess.py:75} INFO - Running command: ['/usr/bin/bash', '-c', 'mysqldump -u root -pmysql@123 -h localhost practise customers > dump_file.sql']
[2024-05-05T02:08:25.953+0000] {subprocess.py:86} INFO - Output:
[2024-05-05T02:08:25.960+0000] {subprocess.py:93} INFO - mysqldump: Got error: 2002: "Can't connect to local server through socket '/run/mysqld/mysqld.sock' (2)" when trying to connect
[2024-05-05T02:08:25.961+0000] {subprocess.py:97} INFO - Command exited with return code 2
[2024-05-05T02:08:25.961+0000] {taskinstance.py:441} INFO - ::group::Post task execution logs
[2024-05-05T02:08:25.974+0000] {taskinstance.py:2890} ERROR - Task failed with exception
Traceback (most recent call last):
  File "/home/airflow/.local/lib/python3.12/site-packages/airflow/models/taskinstance.py", line 465, in _execute_task
    result = _execute_callable(context=context, **execute_callable_kwargs)
             ^^^^^^^^^^^^^^^^^^^^^^^^^^^^^^^^^^^^^^^^^^^^^^^^^^^^^^^^^^^^^
  File "/home/airflow/.local/lib/python3.12/site-packages/airflow/models/taskinstance.py", line 432, in _execute_callable
    return execute_callable(context=context, **execute_callable_kwargs)
           ^^^^^^^^^^^^^^^^^^^^^^^^^^^^^^^^^^^^^^^^^^^^^^^^^^^^^^^^^^^^
  File "/home/airflow/.local/lib/python3.12/site-packages/airflow/models/baseoperator.py", line 400, in wrapper
    return func(self, *args, **kwargs)
           ^^^^^^^^^^^^^^^^^^^^^^^^^^^
  File "/home/airflow/.local/lib/python3.12/site-packages/airflow/operators/bash.py", line 243, in execute
    raise AirflowException(
airflow.exceptions.AirflowException: Bash command failed. The command returned a non-zero exit code 2.
[2024-05-05T02:08:25.979+0000] {taskinstance.py:1205} INFO - Marking task as UP_FOR_RETRY. dag_id=mysql_table_dump, task_id=mysql_table_dump_task, execution_date=20240504T000000, start_date=20240505T020825, end_date=20240505T020825
[2024-05-05T02:08:25.997+0000] {standard_task_runner.py:110} ERROR - Failed to execute job 5 for task mysql_table_dump_task (Bash command failed. The command returned a non-zero exit code 2.; 56)
[2024-05-05T02:08:26.039+0000] {local_task_job_runner.py:240} INFO - Task exited with return code 1
[2024-05-05T02:08:26.065+0000] {taskinstance.py:3482} INFO - 0 downstream tasks scheduled from follow-on schedule check
[2024-05-05T02:08:26.070+0000] {local_task_job_runner.py:222} INFO - ::endgroup::
[2024-05-05T02:10:56.946+0000] {local_task_job_runner.py:120} INFO - ::group::Pre task execution logs
[2024-05-05T02:10:56.970+0000] {taskinstance.py:2073} INFO - Dependencies all met for dep_context=non-requeueable deps ti=<TaskInstance: mysql_table_dump.mysql_table_dump_task scheduled__2024-05-04T00:00:00+00:00 [queued]>
[2024-05-05T02:10:56.980+0000] {taskinstance.py:2073} INFO - Dependencies all met for dep_context=requeueable deps ti=<TaskInstance: mysql_table_dump.mysql_table_dump_task scheduled__2024-05-04T00:00:00+00:00 [queued]>
[2024-05-05T02:10:56.981+0000] {taskinstance.py:2303} INFO - Starting attempt 1 of 2
[2024-05-05T02:10:57.001+0000] {taskinstance.py:2327} INFO - Executing <Task(BashOperator): mysql_table_dump_task> on 2024-05-04 00:00:00+00:00
[2024-05-05T02:10:57.007+0000] {warnings.py:110} WARNING - /home/***/.local/lib/python3.12/site-packages/***/task/task_runner/standard_task_runner.py:61: DeprecationWarning: This process (pid=94) is multi-threaded, use of fork() may lead to deadlocks in the child.
  pid = os.fork()

[2024-05-05T02:10:57.009+0000] {standard_task_runner.py:63} INFO - Started process 95 to run task
[2024-05-05T02:10:57.009+0000] {standard_task_runner.py:90} INFO - Running: ['***', 'tasks', 'run', 'mysql_table_dump', 'mysql_table_dump_task', 'scheduled__2024-05-04T00:00:00+00:00', '--job-id', '6', '--raw', '--subdir', 'DAGS_FOLDER/dump_load_dag.py', '--cfg-path', '/tmp/tmpzeovu_nf']
[2024-05-05T02:10:57.012+0000] {standard_task_runner.py:91} INFO - Job 6: Subtask mysql_table_dump_task
[2024-05-05T02:10:57.063+0000] {task_command.py:426} INFO - Running <TaskInstance: mysql_table_dump.mysql_table_dump_task scheduled__2024-05-04T00:00:00+00:00 [running]> on host 284b5f341ead
[2024-05-05T02:10:57.156+0000] {taskinstance.py:2644} INFO - Exporting env vars: AIRFLOW_CTX_DAG_OWNER='***' AIRFLOW_CTX_DAG_ID='mysql_table_dump' AIRFLOW_CTX_TASK_ID='mysql_table_dump_task' AIRFLOW_CTX_EXECUTION_DATE='2024-05-04T00:00:00+00:00' AIRFLOW_CTX_TRY_NUMBER='1' AIRFLOW_CTX_DAG_RUN_ID='scheduled__2024-05-04T00:00:00+00:00'
[2024-05-05T02:10:57.157+0000] {taskinstance.py:430} INFO - ::endgroup::
[2024-05-05T02:10:57.171+0000] {subprocess.py:63} INFO - Tmp dir root location: /tmp
[2024-05-05T02:10:57.176+0000] {subprocess.py:75} INFO - Running command: ['/usr/bin/bash', '-c', 'mysqldump -u root -pmysql@123 -h localhost practise customers > dump_file.sql']
[2024-05-05T02:10:57.185+0000] {subprocess.py:86} INFO - Output:
[2024-05-05T02:10:57.191+0000] {subprocess.py:93} INFO - mysqldump: Got error: 2002: "Can't connect to local server through socket '/run/mysqld/mysqld.sock' (2)" when trying to connect
[2024-05-05T02:10:57.192+0000] {subprocess.py:97} INFO - Command exited with return code 2
[2024-05-05T02:10:57.193+0000] {taskinstance.py:441} INFO - ::group::Post task execution logs
[2024-05-05T02:10:57.202+0000] {taskinstance.py:2890} ERROR - Task failed with exception
Traceback (most recent call last):
  File "/home/airflow/.local/lib/python3.12/site-packages/airflow/models/taskinstance.py", line 465, in _execute_task
    result = _execute_callable(context=context, **execute_callable_kwargs)
             ^^^^^^^^^^^^^^^^^^^^^^^^^^^^^^^^^^^^^^^^^^^^^^^^^^^^^^^^^^^^^
  File "/home/airflow/.local/lib/python3.12/site-packages/airflow/models/taskinstance.py", line 432, in _execute_callable
    return execute_callable(context=context, **execute_callable_kwargs)
           ^^^^^^^^^^^^^^^^^^^^^^^^^^^^^^^^^^^^^^^^^^^^^^^^^^^^^^^^^^^^
  File "/home/airflow/.local/lib/python3.12/site-packages/airflow/models/baseoperator.py", line 400, in wrapper
    return func(self, *args, **kwargs)
           ^^^^^^^^^^^^^^^^^^^^^^^^^^^
  File "/home/airflow/.local/lib/python3.12/site-packages/airflow/operators/bash.py", line 243, in execute
    raise AirflowException(
airflow.exceptions.AirflowException: Bash command failed. The command returned a non-zero exit code 2.
[2024-05-05T02:10:57.208+0000] {taskinstance.py:1205} INFO - Marking task as UP_FOR_RETRY. dag_id=mysql_table_dump, task_id=mysql_table_dump_task, execution_date=20240504T000000, start_date=20240505T021056, end_date=20240505T021057
[2024-05-05T02:10:57.221+0000] {standard_task_runner.py:110} ERROR - Failed to execute job 6 for task mysql_table_dump_task (Bash command failed. The command returned a non-zero exit code 2.; 95)
[2024-05-05T02:10:57.265+0000] {local_task_job_runner.py:240} INFO - Task exited with return code 1
[2024-05-05T02:10:57.290+0000] {taskinstance.py:3482} INFO - 0 downstream tasks scheduled from follow-on schedule check
[2024-05-05T02:10:57.294+0000] {local_task_job_runner.py:222} INFO - ::endgroup::
