[2024-05-05T04:24:26.608+0000] {local_task_job_runner.py:120} INFO - ::group::Pre task execution logs
[2024-05-05T04:24:26.630+0000] {taskinstance.py:2073} INFO - Dependencies all met for dep_context=non-requeueable deps ti=<TaskInstance: mysql_table_dump.mysql_table_dump_task scheduled__2024-03-14T00:00:00+00:00 [queued]>
[2024-05-05T04:24:26.638+0000] {taskinstance.py:2073} INFO - Dependencies all met for dep_context=requeueable deps ti=<TaskInstance: mysql_table_dump.mysql_table_dump_task scheduled__2024-03-14T00:00:00+00:00 [queued]>
[2024-05-05T04:24:26.639+0000] {taskinstance.py:2303} INFO - Starting attempt 2 of 2
[2024-05-05T04:24:26.652+0000] {taskinstance.py:2327} INFO - Executing <Task(BashOperator): mysql_table_dump_task> on 2024-03-14 00:00:00+00:00
[2024-05-05T04:24:26.659+0000] {warnings.py:110} WARNING - /home/***/.local/lib/python3.12/site-packages/***/task/task_runner/standard_task_runner.py:61: DeprecationWarning: This process (pid=691) is multi-threaded, use of fork() may lead to deadlocks in the child.
  pid = os.fork()

[2024-05-05T04:24:26.661+0000] {standard_task_runner.py:63} INFO - Started process 692 to run task
[2024-05-05T04:24:26.660+0000] {standard_task_runner.py:90} INFO - Running: ['***', 'tasks', 'run', 'mysql_table_dump', 'mysql_table_dump_task', 'scheduled__2024-03-14T00:00:00+00:00', '--job-id', '44', '--raw', '--subdir', 'DAGS_FOLDER/dump_load_dag.py', '--cfg-path', '/tmp/tmplrw7ewf5']
[2024-05-05T04:24:26.662+0000] {standard_task_runner.py:91} INFO - Job 44: Subtask mysql_table_dump_task
[2024-05-05T04:24:26.710+0000] {task_command.py:426} INFO - Running <TaskInstance: mysql_table_dump.mysql_table_dump_task scheduled__2024-03-14T00:00:00+00:00 [running]> on host 284b5f341ead
[2024-05-05T04:24:26.788+0000] {taskinstance.py:2644} INFO - Exporting env vars: AIRFLOW_CTX_DAG_OWNER='***' AIRFLOW_CTX_DAG_ID='mysql_table_dump' AIRFLOW_CTX_TASK_ID='mysql_table_dump_task' AIRFLOW_CTX_EXECUTION_DATE='2024-03-14T00:00:00+00:00' AIRFLOW_CTX_TRY_NUMBER='2' AIRFLOW_CTX_DAG_RUN_ID='scheduled__2024-03-14T00:00:00+00:00'
[2024-05-05T04:24:26.789+0000] {taskinstance.py:430} INFO - ::endgroup::
[2024-05-05T04:24:26.812+0000] {subprocess.py:63} INFO - Tmp dir root location: /tmp
[2024-05-05T04:24:26.813+0000] {subprocess.py:75} INFO - Running command: ['/usr/bin/bash', '-c', 'mysqldump -u root -pmysql@123 -h localhost practise customers > /opt/***/dags/dump_file.sql']
[2024-05-05T04:24:26.821+0000] {subprocess.py:86} INFO - Output:
[2024-05-05T04:24:26.828+0000] {subprocess.py:93} INFO - mysqldump: Got error: 2002: "Can't connect to local server through socket '/run/mysqld/mysqld.sock' (2)" when trying to connect
[2024-05-05T04:24:26.829+0000] {subprocess.py:97} INFO - Command exited with return code 2
[2024-05-05T04:24:26.830+0000] {taskinstance.py:441} INFO - ::group::Post task execution logs
[2024-05-05T04:24:26.840+0000] {taskinstance.py:2890} ERROR - Task failed with exception
Traceback (most recent call last):
  File "/home/airflow/.local/lib/python3.12/site-packages/airflow/models/taskinstance.py", line 465, in _execute_task
    result = _execute_callable(context=context, **execute_callable_kwargs)
             ^^^^^^^^^^^^^^^^^^^^^^^^^^^^^^^^^^^^^^^^^^^^^^^^^^^^^^^^^^^^^
  File "/home/airflow/.local/lib/python3.12/site-packages/airflow/models/taskinstance.py", line 432, in _execute_callable
    return execute_callable(context=context, **execute_callable_kwargs)
           ^^^^^^^^^^^^^^^^^^^^^^^^^^^^^^^^^^^^^^^^^^^^^^^^^^^^^^^^^^^^
  File "/home/airflow/.local/lib/python3.12/site-packages/airflow/models/baseoperator.py", line 400, in wrapper
    return func(self, *args, **kwargs)
           ^^^^^^^^^^^^^^^^^^^^^^^^^^^
  File "/home/airflow/.local/lib/python3.12/site-packages/airflow/operators/bash.py", line 243, in execute
    raise AirflowException(
airflow.exceptions.AirflowException: Bash command failed. The command returned a non-zero exit code 2.
[2024-05-05T04:24:26.844+0000] {taskinstance.py:1205} INFO - Marking task as FAILED. dag_id=mysql_table_dump, task_id=mysql_table_dump_task, execution_date=20240314T000000, start_date=20240505T042426, end_date=20240505T042426
[2024-05-05T04:24:26.858+0000] {standard_task_runner.py:110} ERROR - Failed to execute job 44 for task mysql_table_dump_task (Bash command failed. The command returned a non-zero exit code 2.; 692)
[2024-05-05T04:24:26.876+0000] {local_task_job_runner.py:240} INFO - Task exited with return code 1
[2024-05-05T04:24:26.890+0000] {taskinstance.py:3482} INFO - 0 downstream tasks scheduled from follow-on schedule check
[2024-05-05T04:24:26.893+0000] {local_task_job_runner.py:222} INFO - ::endgroup::
[2024-05-05T05:28:58.911+0000] {local_task_job_runner.py:120} INFO - ::group::Pre task execution logs
[2024-05-05T05:28:58.930+0000] {taskinstance.py:2073} INFO - Dependencies all met for dep_context=non-requeueable deps ti=<TaskInstance: mysql_table_dump.mysql_table_dump_task scheduled__2024-03-14T00:00:00+00:00 [queued]>
[2024-05-05T05:28:58.938+0000] {taskinstance.py:2073} INFO - Dependencies all met for dep_context=requeueable deps ti=<TaskInstance: mysql_table_dump.mysql_table_dump_task scheduled__2024-03-14T00:00:00+00:00 [queued]>
[2024-05-05T05:28:58.939+0000] {taskinstance.py:2303} INFO - Starting attempt 2 of 2
[2024-05-05T05:28:58.957+0000] {taskinstance.py:2327} INFO - Executing <Task(BashOperator): mysql_table_dump_task> on 2024-03-14 00:00:00+00:00
[2024-05-05T05:28:58.961+0000] {warnings.py:110} WARNING - /home/***/.local/lib/python3.12/site-packages/***/task/task_runner/standard_task_runner.py:61: DeprecationWarning: This process (pid=65) is multi-threaded, use of fork() may lead to deadlocks in the child.
  pid = os.fork()

[2024-05-05T05:28:58.963+0000] {standard_task_runner.py:63} INFO - Started process 66 to run task
[2024-05-05T05:28:58.964+0000] {standard_task_runner.py:90} INFO - Running: ['***', 'tasks', 'run', 'mysql_table_dump', 'mysql_table_dump_task', 'scheduled__2024-03-14T00:00:00+00:00', '--job-id', '57', '--raw', '--subdir', 'DAGS_FOLDER/dump_load_dag.py', '--cfg-path', '/tmp/tmp41zwviah']
[2024-05-05T05:28:58.966+0000] {standard_task_runner.py:91} INFO - Job 57: Subtask mysql_table_dump_task
[2024-05-05T05:28:59.011+0000] {task_command.py:426} INFO - Running <TaskInstance: mysql_table_dump.mysql_table_dump_task scheduled__2024-03-14T00:00:00+00:00 [running]> on host 284b5f341ead
[2024-05-05T05:28:59.080+0000] {taskinstance.py:2644} INFO - Exporting env vars: AIRFLOW_CTX_DAG_OWNER='***' AIRFLOW_CTX_DAG_ID='mysql_table_dump' AIRFLOW_CTX_TASK_ID='mysql_table_dump_task' AIRFLOW_CTX_EXECUTION_DATE='2024-03-14T00:00:00+00:00' AIRFLOW_CTX_TRY_NUMBER='2' AIRFLOW_CTX_DAG_RUN_ID='scheduled__2024-03-14T00:00:00+00:00'
[2024-05-05T05:28:59.081+0000] {taskinstance.py:430} INFO - ::endgroup::
[2024-05-05T05:28:59.091+0000] {subprocess.py:63} INFO - Tmp dir root location: /tmp
[2024-05-05T05:28:59.093+0000] {subprocess.py:75} INFO - Running command: ['/usr/bin/bash', '-c', 'mysqldump -u root -pmysql@123 -h localhost practise customers > /opt/***/dags/dump_file.sql']
[2024-05-05T05:28:59.100+0000] {subprocess.py:86} INFO - Output:
[2024-05-05T05:28:59.107+0000] {subprocess.py:93} INFO - mysqldump: Got error: 2002: "Can't connect to local server through socket '/run/mysqld/mysqld.sock' (2)" when trying to connect
[2024-05-05T05:28:59.108+0000] {subprocess.py:97} INFO - Command exited with return code 2
[2024-05-05T05:28:59.109+0000] {taskinstance.py:441} INFO - ::group::Post task execution logs
[2024-05-05T05:28:59.118+0000] {taskinstance.py:2890} ERROR - Task failed with exception
Traceback (most recent call last):
  File "/home/airflow/.local/lib/python3.12/site-packages/airflow/models/taskinstance.py", line 465, in _execute_task
    result = _execute_callable(context=context, **execute_callable_kwargs)
             ^^^^^^^^^^^^^^^^^^^^^^^^^^^^^^^^^^^^^^^^^^^^^^^^^^^^^^^^^^^^^
  File "/home/airflow/.local/lib/python3.12/site-packages/airflow/models/taskinstance.py", line 432, in _execute_callable
    return execute_callable(context=context, **execute_callable_kwargs)
           ^^^^^^^^^^^^^^^^^^^^^^^^^^^^^^^^^^^^^^^^^^^^^^^^^^^^^^^^^^^^
  File "/home/airflow/.local/lib/python3.12/site-packages/airflow/models/baseoperator.py", line 400, in wrapper
    return func(self, *args, **kwargs)
           ^^^^^^^^^^^^^^^^^^^^^^^^^^^
  File "/home/airflow/.local/lib/python3.12/site-packages/airflow/operators/bash.py", line 243, in execute
    raise AirflowException(
airflow.exceptions.AirflowException: Bash command failed. The command returned a non-zero exit code 2.
[2024-05-05T05:28:59.123+0000] {taskinstance.py:1205} INFO - Marking task as FAILED. dag_id=mysql_table_dump, task_id=mysql_table_dump_task, execution_date=20240314T000000, start_date=20240505T052858, end_date=20240505T052859
[2024-05-05T05:28:59.135+0000] {standard_task_runner.py:110} ERROR - Failed to execute job 57 for task mysql_table_dump_task (Bash command failed. The command returned a non-zero exit code 2.; 66)
[2024-05-05T05:28:59.179+0000] {local_task_job_runner.py:240} INFO - Task exited with return code 1
[2024-05-05T05:28:59.193+0000] {taskinstance.py:3482} INFO - 0 downstream tasks scheduled from follow-on schedule check
[2024-05-05T05:28:59.198+0000] {local_task_job_runner.py:222} INFO - ::endgroup::
