[2024-05-05T03:46:23.104+0000] {local_task_job_runner.py:120} INFO - ::group::Pre task execution logs
[2024-05-05T03:46:23.129+0000] {taskinstance.py:2073} INFO - Dependencies all met for dep_context=non-requeueable deps ti=<TaskInstance: bash.bash_curl manual__2024-05-05T03:46:22.085557+00:00 [queued]>
[2024-05-05T03:46:23.138+0000] {taskinstance.py:2073} INFO - Dependencies all met for dep_context=requeueable deps ti=<TaskInstance: bash.bash_curl manual__2024-05-05T03:46:22.085557+00:00 [queued]>
[2024-05-05T03:46:23.139+0000] {taskinstance.py:2303} INFO - Starting attempt 1 of 2
[2024-05-05T03:46:23.156+0000] {taskinstance.py:2327} INFO - Executing <Task(BashOperator): bash_curl> on 2024-05-05 03:46:22.085557+00:00
[2024-05-05T03:46:23.163+0000] {warnings.py:110} WARNING - /home/***/.local/lib/python3.12/site-packages/***/task/task_runner/standard_task_runner.py:61: DeprecationWarning: This process (pid=154) is multi-threaded, use of fork() may lead to deadlocks in the child.
  pid = os.fork()

[2024-05-05T03:46:23.166+0000] {standard_task_runner.py:63} INFO - Started process 155 to run task
[2024-05-05T03:46:23.165+0000] {standard_task_runner.py:90} INFO - Running: ['***', 'tasks', 'run', 'bash', 'bash_curl', 'manual__2024-05-05T03:46:22.085557+00:00', '--job-id', '33', '--raw', '--subdir', 'DAGS_FOLDER/bash_dag.py', '--cfg-path', '/tmp/tmpf4cwd4wp']
[2024-05-05T03:46:23.168+0000] {standard_task_runner.py:91} INFO - Job 33: Subtask bash_curl
[2024-05-05T03:46:23.220+0000] {task_command.py:426} INFO - Running <TaskInstance: bash.bash_curl manual__2024-05-05T03:46:22.085557+00:00 [running]> on host 284b5f341ead
[2024-05-05T03:46:23.322+0000] {taskinstance.py:2644} INFO - Exporting env vars: AIRFLOW_CTX_DAG_OWNER='***' AIRFLOW_CTX_DAG_ID='bash' AIRFLOW_CTX_TASK_ID='bash_curl' AIRFLOW_CTX_EXECUTION_DATE='2024-05-05T03:46:22.085557+00:00' AIRFLOW_CTX_TRY_NUMBER='1' AIRFLOW_CTX_DAG_RUN_ID='manual__2024-05-05T03:46:22.085557+00:00'
[2024-05-05T03:46:23.324+0000] {taskinstance.py:430} INFO - ::endgroup::
[2024-05-05T03:46:23.342+0000] {subprocess.py:63} INFO - Tmp dir root location: /tmp
[2024-05-05T03:46:23.344+0000] {subprocess.py:75} INFO - Running command: ['/usr/bin/bash', '-c', 'curl -o xrate.csv "https://data-api.ecb.europa.eu/service/data/EXR/M.USD.EUR.SP00.A?format=csvdata']
[2024-05-05T03:46:23.354+0000] {subprocess.py:86} INFO - Output:
[2024-05-05T03:46:23.356+0000] {subprocess.py:93} INFO - /usr/bin/bash: -c: line 1: unexpected EOF while looking for matching `"'
[2024-05-05T03:46:23.357+0000] {subprocess.py:97} INFO - Command exited with return code 2
[2024-05-05T03:46:23.358+0000] {taskinstance.py:441} INFO - ::group::Post task execution logs
[2024-05-05T03:46:23.370+0000] {taskinstance.py:2890} ERROR - Task failed with exception
Traceback (most recent call last):
  File "/home/airflow/.local/lib/python3.12/site-packages/airflow/models/taskinstance.py", line 465, in _execute_task
    result = _execute_callable(context=context, **execute_callable_kwargs)
             ^^^^^^^^^^^^^^^^^^^^^^^^^^^^^^^^^^^^^^^^^^^^^^^^^^^^^^^^^^^^^
  File "/home/airflow/.local/lib/python3.12/site-packages/airflow/models/taskinstance.py", line 432, in _execute_callable
    return execute_callable(context=context, **execute_callable_kwargs)
           ^^^^^^^^^^^^^^^^^^^^^^^^^^^^^^^^^^^^^^^^^^^^^^^^^^^^^^^^^^^^
  File "/home/airflow/.local/lib/python3.12/site-packages/airflow/models/baseoperator.py", line 400, in wrapper
    return func(self, *args, **kwargs)
           ^^^^^^^^^^^^^^^^^^^^^^^^^^^
  File "/home/airflow/.local/lib/python3.12/site-packages/airflow/operators/bash.py", line 243, in execute
    raise AirflowException(
airflow.exceptions.AirflowException: Bash command failed. The command returned a non-zero exit code 2.
[2024-05-05T03:46:23.375+0000] {taskinstance.py:1205} INFO - Marking task as UP_FOR_RETRY. dag_id=bash, task_id=bash_curl, execution_date=20240505T034622, start_date=20240505T034623, end_date=20240505T034623
[2024-05-05T03:46:23.394+0000] {standard_task_runner.py:110} ERROR - Failed to execute job 33 for task bash_curl (Bash command failed. The command returned a non-zero exit code 2.; 155)
[2024-05-05T03:46:23.421+0000] {local_task_job_runner.py:240} INFO - Task exited with return code 1
[2024-05-05T03:46:23.440+0000] {taskinstance.py:3482} INFO - 0 downstream tasks scheduled from follow-on schedule check
[2024-05-05T03:46:23.444+0000] {local_task_job_runner.py:222} INFO - ::endgroup::
