[2024-05-05T03:39:49.726+0000] {local_task_job_runner.py:120} INFO - ::group::Pre task execution logs
[2024-05-05T03:39:49.755+0000] {taskinstance.py:2073} INFO - Dependencies all met for dep_context=non-requeueable deps ti=<TaskInstance: bash.bash_command scheduled__2024-03-14T00:00:00+00:00 [queued]>
[2024-05-05T03:39:49.767+0000] {taskinstance.py:2073} INFO - Dependencies all met for dep_context=requeueable deps ti=<TaskInstance: bash.bash_command scheduled__2024-03-14T00:00:00+00:00 [queued]>
[2024-05-05T03:39:49.767+0000] {taskinstance.py:2303} INFO - Starting attempt 1 of 2
[2024-05-05T03:39:49.786+0000] {taskinstance.py:2327} INFO - Executing <Task(BashOperator): bash_command> on 2024-03-14 00:00:00+00:00
[2024-05-05T03:39:49.791+0000] {warnings.py:110} WARNING - /home/***/.local/lib/python3.12/site-packages/***/task/task_runner/standard_task_runner.py:61: DeprecationWarning: This process (pid=55) is multi-threaded, use of fork() may lead to deadlocks in the child.
  pid = os.fork()

[2024-05-05T03:39:49.793+0000] {standard_task_runner.py:63} INFO - Started process 57 to run task
[2024-05-05T03:39:49.793+0000] {standard_task_runner.py:90} INFO - Running: ['***', 'tasks', 'run', 'bash', 'bash_command', 'scheduled__2024-03-14T00:00:00+00:00', '--job-id', '28', '--raw', '--subdir', 'DAGS_FOLDER/bash_dag.py', '--cfg-path', '/tmp/tmpx8lukq6t']
[2024-05-05T03:39:49.796+0000] {standard_task_runner.py:91} INFO - Job 28: Subtask bash_command
[2024-05-05T03:39:49.853+0000] {task_command.py:426} INFO - Running <TaskInstance: bash.bash_command scheduled__2024-03-14T00:00:00+00:00 [running]> on host 284b5f341ead
[2024-05-05T03:39:49.953+0000] {taskinstance.py:2644} INFO - Exporting env vars: AIRFLOW_CTX_DAG_OWNER='***' AIRFLOW_CTX_DAG_ID='bash' AIRFLOW_CTX_TASK_ID='bash_command' AIRFLOW_CTX_EXECUTION_DATE='2024-03-14T00:00:00+00:00' AIRFLOW_CTX_TRY_NUMBER='1' AIRFLOW_CTX_DAG_RUN_ID='scheduled__2024-03-14T00:00:00+00:00'
[2024-05-05T03:39:49.954+0000] {taskinstance.py:430} INFO - ::endgroup::
[2024-05-05T03:39:49.974+0000] {subprocess.py:63} INFO - Tmp dir root location: /tmp
[2024-05-05T03:39:49.976+0000] {subprocess.py:75} INFO - Running command: ['/usr/bin/bash', '-c', 'curl -o xrate.csv "https://data-api.ecb.europa.eu/service/data/EXR/M.USD.EUR.SP00.A?format=csvdata']
[2024-05-05T03:39:49.986+0000] {subprocess.py:86} INFO - Output:
[2024-05-05T03:39:49.987+0000] {subprocess.py:93} INFO - /usr/bin/bash: -c: line 1: unexpected EOF while looking for matching `"'
[2024-05-05T03:39:49.988+0000] {subprocess.py:97} INFO - Command exited with return code 2
[2024-05-05T03:39:49.989+0000] {taskinstance.py:441} INFO - ::group::Post task execution logs
[2024-05-05T03:39:50.002+0000] {taskinstance.py:2890} ERROR - Task failed with exception
Traceback (most recent call last):
  File "/home/airflow/.local/lib/python3.12/site-packages/airflow/models/taskinstance.py", line 465, in _execute_task
    result = _execute_callable(context=context, **execute_callable_kwargs)
             ^^^^^^^^^^^^^^^^^^^^^^^^^^^^^^^^^^^^^^^^^^^^^^^^^^^^^^^^^^^^^
  File "/home/airflow/.local/lib/python3.12/site-packages/airflow/models/taskinstance.py", line 432, in _execute_callable
    return execute_callable(context=context, **execute_callable_kwargs)
           ^^^^^^^^^^^^^^^^^^^^^^^^^^^^^^^^^^^^^^^^^^^^^^^^^^^^^^^^^^^^
  File "/home/airflow/.local/lib/python3.12/site-packages/airflow/models/baseoperator.py", line 400, in wrapper
    return func(self, *args, **kwargs)
           ^^^^^^^^^^^^^^^^^^^^^^^^^^^
  File "/home/airflow/.local/lib/python3.12/site-packages/airflow/operators/bash.py", line 243, in execute
    raise AirflowException(
airflow.exceptions.AirflowException: Bash command failed. The command returned a non-zero exit code 2.
[2024-05-05T03:39:50.007+0000] {taskinstance.py:1205} INFO - Marking task as UP_FOR_RETRY. dag_id=bash, task_id=bash_command, execution_date=20240314T000000, start_date=20240505T033949, end_date=20240505T033950
[2024-05-05T03:39:50.024+0000] {standard_task_runner.py:110} ERROR - Failed to execute job 28 for task bash_command (Bash command failed. The command returned a non-zero exit code 2.; 57)
[2024-05-05T03:39:50.050+0000] {local_task_job_runner.py:240} INFO - Task exited with return code 1
[2024-05-05T03:39:50.065+0000] {taskinstance.py:3482} INFO - 0 downstream tasks scheduled from follow-on schedule check
[2024-05-05T03:39:50.068+0000] {local_task_job_runner.py:222} INFO - ::endgroup::
