[2024-05-05T03:57:12.761+0000] {local_task_job_runner.py:120} INFO - ::group::Pre task execution logs
[2024-05-05T03:57:12.780+0000] {taskinstance.py:2073} INFO - Dependencies all met for dep_context=non-requeueable deps ti=<TaskInstance: bash.bash_curl manual__2024-05-05T03:57:11.277730+00:00 [queued]>
[2024-05-05T03:57:12.788+0000] {taskinstance.py:2073} INFO - Dependencies all met for dep_context=requeueable deps ti=<TaskInstance: bash.bash_curl manual__2024-05-05T03:57:11.277730+00:00 [queued]>
[2024-05-05T03:57:12.789+0000] {taskinstance.py:2303} INFO - Starting attempt 1 of 2
[2024-05-05T03:57:12.804+0000] {taskinstance.py:2327} INFO - Executing <Task(BashOperator): bash_curl> on 2024-05-05 03:57:11.277730+00:00
[2024-05-05T03:57:12.810+0000] {warnings.py:110} WARNING - /home/***/.local/lib/python3.12/site-packages/***/task/task_runner/standard_task_runner.py:61: DeprecationWarning: This process (pid=302) is multi-threaded, use of fork() may lead to deadlocks in the child.
  pid = os.fork()

[2024-05-05T03:57:12.811+0000] {standard_task_runner.py:63} INFO - Started process 303 to run task
[2024-05-05T03:57:12.811+0000] {standard_task_runner.py:90} INFO - Running: ['***', 'tasks', 'run', 'bash', 'bash_curl', 'manual__2024-05-05T03:57:11.277730+00:00', '--job-id', '36', '--raw', '--subdir', 'DAGS_FOLDER/bash_dag.py', '--cfg-path', '/tmp/tmpyhmr29_1']
[2024-05-05T03:57:12.813+0000] {standard_task_runner.py:91} INFO - Job 36: Subtask bash_curl
[2024-05-05T03:57:12.861+0000] {task_command.py:426} INFO - Running <TaskInstance: bash.bash_curl manual__2024-05-05T03:57:11.277730+00:00 [running]> on host 284b5f341ead
[2024-05-05T03:57:12.944+0000] {taskinstance.py:2644} INFO - Exporting env vars: AIRFLOW_CTX_DAG_OWNER='***' AIRFLOW_CTX_DAG_ID='bash' AIRFLOW_CTX_TASK_ID='bash_curl' AIRFLOW_CTX_EXECUTION_DATE='2024-05-05T03:57:11.277730+00:00' AIRFLOW_CTX_TRY_NUMBER='1' AIRFLOW_CTX_DAG_RUN_ID='manual__2024-05-05T03:57:11.277730+00:00'
[2024-05-05T03:57:12.946+0000] {taskinstance.py:430} INFO - ::endgroup::
[2024-05-05T03:57:12.957+0000] {subprocess.py:63} INFO - Tmp dir root location: /tmp
[2024-05-05T03:57:12.959+0000] {subprocess.py:75} INFO - Running command: ['/usr/bin/bash', '-c', 'curl -o tmp/xrate.csv "https://data-api.ecb.europa.eu/service/data/EXR/M.USD.EUR.SP00.A?format=csvdata"']
[2024-05-05T03:57:12.966+0000] {subprocess.py:86} INFO - Output:
[2024-05-05T03:57:12.973+0000] {subprocess.py:93} INFO -   % Total    % Received % Xferd  Average Speed   Time    Time     Time  Current
[2024-05-05T03:57:12.974+0000] {subprocess.py:93} INFO -                                  Dload  Upload   Total   Spent    Left  Speed
[2024-05-05T03:57:14.350+0000] {subprocess.py:93} INFO -   0     0    0     0    0     0      0      0 --:--:-- --:--:-- --:--:--     0  0     0    0     0    0     0      0      0 --:--:-- --:--:-- --:--:--     0  0     0    0     0    0     0      0      0 --:--:--  0:00:01 --:--:--     0Warning: Failed to open the file tmp/xrate.csv: No such file or directory
[2024-05-05T03:57:14.351+0000] {subprocess.py:93} INFO - 100 16170    0 16170    0     0  11743      0 --:--:--  0:00:01 --:--:-- 11742
[2024-05-05T03:57:14.351+0000] {subprocess.py:93} INFO - curl: (23) Failure writing output to destination
[2024-05-05T03:57:14.352+0000] {subprocess.py:97} INFO - Command exited with return code 23
[2024-05-05T03:57:14.353+0000] {taskinstance.py:441} INFO - ::group::Post task execution logs
[2024-05-05T03:57:14.364+0000] {taskinstance.py:2890} ERROR - Task failed with exception
Traceback (most recent call last):
  File "/home/airflow/.local/lib/python3.12/site-packages/airflow/models/taskinstance.py", line 465, in _execute_task
    result = _execute_callable(context=context, **execute_callable_kwargs)
             ^^^^^^^^^^^^^^^^^^^^^^^^^^^^^^^^^^^^^^^^^^^^^^^^^^^^^^^^^^^^^
  File "/home/airflow/.local/lib/python3.12/site-packages/airflow/models/taskinstance.py", line 432, in _execute_callable
    return execute_callable(context=context, **execute_callable_kwargs)
           ^^^^^^^^^^^^^^^^^^^^^^^^^^^^^^^^^^^^^^^^^^^^^^^^^^^^^^^^^^^^
  File "/home/airflow/.local/lib/python3.12/site-packages/airflow/models/baseoperator.py", line 400, in wrapper
    return func(self, *args, **kwargs)
           ^^^^^^^^^^^^^^^^^^^^^^^^^^^
  File "/home/airflow/.local/lib/python3.12/site-packages/airflow/operators/bash.py", line 243, in execute
    raise AirflowException(
airflow.exceptions.AirflowException: Bash command failed. The command returned a non-zero exit code 23.
[2024-05-05T03:57:14.368+0000] {taskinstance.py:1205} INFO - Marking task as UP_FOR_RETRY. dag_id=bash, task_id=bash_curl, execution_date=20240505T035711, start_date=20240505T035712, end_date=20240505T035714
[2024-05-05T03:57:14.383+0000] {standard_task_runner.py:110} ERROR - Failed to execute job 36 for task bash_curl (Bash command failed. The command returned a non-zero exit code 23.; 303)
[2024-05-05T03:57:14.396+0000] {local_task_job_runner.py:240} INFO - Task exited with return code 1
[2024-05-05T03:57:14.416+0000] {taskinstance.py:3482} INFO - 0 downstream tasks scheduled from follow-on schedule check
[2024-05-05T03:57:14.419+0000] {local_task_job_runner.py:222} INFO - ::endgroup::
