[2024-05-07T09:48:53.241+0000] {local_task_job_runner.py:120} INFO - ::group::Pre task execution logs
[2024-05-07T09:48:53.266+0000] {taskinstance.py:2073} INFO - Dependencies all met for dep_context=non-requeueable deps ti=<TaskInstance: mysql_table_dump.mysql_table_dump_task manual__2024-05-07T09:48:51.895877+00:00 [queued]>
[2024-05-07T09:48:53.275+0000] {taskinstance.py:2073} INFO - Dependencies all met for dep_context=requeueable deps ti=<TaskInstance: mysql_table_dump.mysql_table_dump_task manual__2024-05-07T09:48:51.895877+00:00 [queued]>
[2024-05-07T09:48:53.276+0000] {taskinstance.py:2303} INFO - Starting attempt 1 of 1
[2024-05-07T09:48:53.291+0000] {taskinstance.py:2327} INFO - Executing <Task(BashOperator): mysql_table_dump_task> on 2024-05-07 09:48:51.895877+00:00
[2024-05-07T09:48:53.297+0000] {warnings.py:110} WARNING - /home/***/.local/lib/python3.12/site-packages/***/task/task_runner/standard_task_runner.py:61: DeprecationWarning: This process (pid=821) is multi-threaded, use of fork() may lead to deadlocks in the child.
  pid = os.fork()

[2024-05-07T09:48:53.298+0000] {standard_task_runner.py:63} INFO - Started process 822 to run task
[2024-05-07T09:48:53.298+0000] {standard_task_runner.py:90} INFO - Running: ['***', 'tasks', 'run', 'mysql_table_dump', 'mysql_table_dump_task', 'manual__2024-05-07T09:48:51.895877+00:00', '--job-id', '78', '--raw', '--subdir', 'DAGS_FOLDER/dump_load_dag.py', '--cfg-path', '/tmp/tmpjjz1v0di']
[2024-05-07T09:48:53.301+0000] {standard_task_runner.py:91} INFO - Job 78: Subtask mysql_table_dump_task
[2024-05-07T09:48:53.355+0000] {task_command.py:426} INFO - Running <TaskInstance: mysql_table_dump.mysql_table_dump_task manual__2024-05-07T09:48:51.895877+00:00 [running]> on host 284b5f341ead
[2024-05-07T09:48:53.451+0000] {taskinstance.py:2644} INFO - Exporting env vars: AIRFLOW_CTX_DAG_OWNER='***' AIRFLOW_CTX_DAG_ID='mysql_table_dump' AIRFLOW_CTX_TASK_ID='mysql_table_dump_task' AIRFLOW_CTX_EXECUTION_DATE='2024-05-07T09:48:51.895877+00:00' AIRFLOW_CTX_TRY_NUMBER='1' AIRFLOW_CTX_DAG_RUN_ID='manual__2024-05-07T09:48:51.895877+00:00'
[2024-05-07T09:48:53.452+0000] {taskinstance.py:430} INFO - ::endgroup::
[2024-05-07T09:48:53.465+0000] {subprocess.py:63} INFO - Tmp dir root location: /tmp
[2024-05-07T09:48:53.467+0000] {subprocess.py:75} INFO - Running command: ['/usr/bin/bash', '-c', 'mysqldump -u root -proot -h 127.0.0.1 -P 3306 fc_facts facts > /opt/***/dags/dump_file.sql 2>/opt/***/dags/dump_error.log']
[2024-05-07T09:48:53.474+0000] {subprocess.py:86} INFO - Output:
[2024-05-07T09:48:53.487+0000] {subprocess.py:97} INFO - Command exited with return code 2
[2024-05-07T09:48:53.488+0000] {taskinstance.py:441} INFO - ::group::Post task execution logs
[2024-05-07T09:48:53.499+0000] {taskinstance.py:2890} ERROR - Task failed with exception
Traceback (most recent call last):
  File "/home/airflow/.local/lib/python3.12/site-packages/airflow/models/taskinstance.py", line 465, in _execute_task
    result = _execute_callable(context=context, **execute_callable_kwargs)
             ^^^^^^^^^^^^^^^^^^^^^^^^^^^^^^^^^^^^^^^^^^^^^^^^^^^^^^^^^^^^^
  File "/home/airflow/.local/lib/python3.12/site-packages/airflow/models/taskinstance.py", line 432, in _execute_callable
    return execute_callable(context=context, **execute_callable_kwargs)
           ^^^^^^^^^^^^^^^^^^^^^^^^^^^^^^^^^^^^^^^^^^^^^^^^^^^^^^^^^^^^
  File "/home/airflow/.local/lib/python3.12/site-packages/airflow/models/baseoperator.py", line 400, in wrapper
    return func(self, *args, **kwargs)
           ^^^^^^^^^^^^^^^^^^^^^^^^^^^
  File "/home/airflow/.local/lib/python3.12/site-packages/airflow/operators/bash.py", line 243, in execute
    raise AirflowException(
airflow.exceptions.AirflowException: Bash command failed. The command returned a non-zero exit code 2.
[2024-05-07T09:48:53.504+0000] {taskinstance.py:1205} INFO - Marking task as FAILED. dag_id=mysql_table_dump, task_id=mysql_table_dump_task, execution_date=20240507T094851, start_date=20240507T094853, end_date=20240507T094853
[2024-05-07T09:48:53.519+0000] {standard_task_runner.py:110} ERROR - Failed to execute job 78 for task mysql_table_dump_task (Bash command failed. The command returned a non-zero exit code 2.; 822)
[2024-05-07T09:48:53.553+0000] {local_task_job_runner.py:240} INFO - Task exited with return code 1
[2024-05-07T09:48:53.567+0000] {taskinstance.py:3482} INFO - 0 downstream tasks scheduled from follow-on schedule check
[2024-05-07T09:48:53.571+0000] {local_task_job_runner.py:222} INFO - ::endgroup::
