[2024-05-05T03:34:55.356+0000] {local_task_job_runner.py:120} INFO - ::group::Pre task execution logs
[2024-05-05T03:34:55.376+0000] {taskinstance.py:2073} INFO - Dependencies all met for dep_context=non-requeueable deps ti=<TaskInstance: bash.bash_command manual__2024-05-05T03:33:41.572808+00:00 [queued]>
[2024-05-05T03:34:55.384+0000] {taskinstance.py:2073} INFO - Dependencies all met for dep_context=requeueable deps ti=<TaskInstance: bash.bash_command manual__2024-05-05T03:33:41.572808+00:00 [queued]>
[2024-05-05T03:34:55.385+0000] {taskinstance.py:2303} INFO - Starting attempt 2 of 2
[2024-05-05T03:34:55.400+0000] {taskinstance.py:2327} INFO - Executing <Task(BashOperator): bash_command> on 2024-05-05 03:33:41.572808+00:00
[2024-05-05T03:34:55.405+0000] {warnings.py:110} WARNING - /home/***/.local/lib/python3.12/site-packages/***/task/task_runner/standard_task_runner.py:61: DeprecationWarning: This process (pid=140) is multi-threaded, use of fork() may lead to deadlocks in the child.
  pid = os.fork()

[2024-05-05T03:34:55.406+0000] {standard_task_runner.py:63} INFO - Started process 141 to run task
[2024-05-05T03:34:55.406+0000] {standard_task_runner.py:90} INFO - Running: ['***', 'tasks', 'run', 'bash', 'bash_command', 'manual__2024-05-05T03:33:41.572808+00:00', '--job-id', '23', '--raw', '--subdir', 'DAGS_FOLDER/bash_dag.py', '--cfg-path', '/tmp/tmps90g4y3i']
[2024-05-05T03:34:55.409+0000] {standard_task_runner.py:91} INFO - Job 23: Subtask bash_command
[2024-05-05T03:34:55.457+0000] {task_command.py:426} INFO - Running <TaskInstance: bash.bash_command manual__2024-05-05T03:33:41.572808+00:00 [running]> on host 284b5f341ead
[2024-05-05T03:34:55.548+0000] {taskinstance.py:2644} INFO - Exporting env vars: AIRFLOW_CTX_DAG_OWNER='***' AIRFLOW_CTX_DAG_ID='bash' AIRFLOW_CTX_TASK_ID='bash_command' AIRFLOW_CTX_EXECUTION_DATE='2024-05-05T03:33:41.572808+00:00' AIRFLOW_CTX_TRY_NUMBER='2' AIRFLOW_CTX_DAG_RUN_ID='manual__2024-05-05T03:33:41.572808+00:00'
[2024-05-05T03:34:55.549+0000] {taskinstance.py:430} INFO - ::endgroup::
[2024-05-05T03:34:55.563+0000] {subprocess.py:63} INFO - Tmp dir root location: /tmp
[2024-05-05T03:34:55.564+0000] {subprocess.py:75} INFO - Running command: ['/usr/bin/bash', '-c', 'curl -o tmp/xrate.csv "https://data-api.ecb.europa.eu/service/data/EXR/M.USD.EUR.SP00.A?format=csvdata']
[2024-05-05T03:34:55.571+0000] {subprocess.py:86} INFO - Output:
[2024-05-05T03:34:55.572+0000] {subprocess.py:93} INFO - /usr/bin/bash: -c: line 1: unexpected EOF while looking for matching `"'
[2024-05-05T03:34:55.573+0000] {subprocess.py:97} INFO - Command exited with return code 2
[2024-05-05T03:34:55.574+0000] {taskinstance.py:441} INFO - ::group::Post task execution logs
[2024-05-05T03:34:55.586+0000] {taskinstance.py:2890} ERROR - Task failed with exception
Traceback (most recent call last):
  File "/home/airflow/.local/lib/python3.12/site-packages/airflow/models/taskinstance.py", line 465, in _execute_task
    result = _execute_callable(context=context, **execute_callable_kwargs)
             ^^^^^^^^^^^^^^^^^^^^^^^^^^^^^^^^^^^^^^^^^^^^^^^^^^^^^^^^^^^^^
  File "/home/airflow/.local/lib/python3.12/site-packages/airflow/models/taskinstance.py", line 432, in _execute_callable
    return execute_callable(context=context, **execute_callable_kwargs)
           ^^^^^^^^^^^^^^^^^^^^^^^^^^^^^^^^^^^^^^^^^^^^^^^^^^^^^^^^^^^^
  File "/home/airflow/.local/lib/python3.12/site-packages/airflow/models/baseoperator.py", line 400, in wrapper
    return func(self, *args, **kwargs)
           ^^^^^^^^^^^^^^^^^^^^^^^^^^^
  File "/home/airflow/.local/lib/python3.12/site-packages/airflow/operators/bash.py", line 243, in execute
    raise AirflowException(
airflow.exceptions.AirflowException: Bash command failed. The command returned a non-zero exit code 2.
[2024-05-05T03:34:55.591+0000] {taskinstance.py:1205} INFO - Marking task as FAILED. dag_id=bash, task_id=bash_command, execution_date=20240505T033341, start_date=20240505T033455, end_date=20240505T033455
[2024-05-05T03:34:55.603+0000] {standard_task_runner.py:110} ERROR - Failed to execute job 23 for task bash_command (Bash command failed. The command returned a non-zero exit code 2.; 141)
[2024-05-05T03:34:55.621+0000] {local_task_job_runner.py:240} INFO - Task exited with return code 1
[2024-05-05T03:34:55.636+0000] {taskinstance.py:3482} INFO - 0 downstream tasks scheduled from follow-on schedule check
[2024-05-05T03:34:55.640+0000] {local_task_job_runner.py:222} INFO - ::endgroup::
