[2024-05-05T03:33:53.914+0000] {local_task_job_runner.py:120} INFO - ::group::Pre task execution logs
[2024-05-05T03:33:53.940+0000] {taskinstance.py:2073} INFO - Dependencies all met for dep_context=non-requeueable deps ti=<TaskInstance: bash.bash_command manual__2024-05-05T03:33:41.572808+00:00 [queued]>
[2024-05-05T03:33:53.950+0000] {taskinstance.py:2073} INFO - Dependencies all met for dep_context=requeueable deps ti=<TaskInstance: bash.bash_command manual__2024-05-05T03:33:41.572808+00:00 [queued]>
[2024-05-05T03:33:53.951+0000] {taskinstance.py:2303} INFO - Starting attempt 1 of 2
[2024-05-05T03:33:53.969+0000] {taskinstance.py:2327} INFO - Executing <Task(BashOperator): bash_command> on 2024-05-05 03:33:41.572808+00:00
[2024-05-05T03:33:53.974+0000] {warnings.py:110} WARNING - /home/***/.local/lib/python3.12/site-packages/***/task/task_runner/standard_task_runner.py:61: DeprecationWarning: This process (pid=123) is multi-threaded, use of fork() may lead to deadlocks in the child.
  pid = os.fork()

[2024-05-05T03:33:53.976+0000] {standard_task_runner.py:63} INFO - Started process 124 to run task
[2024-05-05T03:33:53.975+0000] {standard_task_runner.py:90} INFO - Running: ['***', 'tasks', 'run', 'bash', 'bash_command', 'manual__2024-05-05T03:33:41.572808+00:00', '--job-id', '22', '--raw', '--subdir', 'DAGS_FOLDER/bash_dag.py', '--cfg-path', '/tmp/tmpq1n3gasy']
[2024-05-05T03:33:53.978+0000] {standard_task_runner.py:91} INFO - Job 22: Subtask bash_command
[2024-05-05T03:33:54.025+0000] {task_command.py:426} INFO - Running <TaskInstance: bash.bash_command manual__2024-05-05T03:33:41.572808+00:00 [running]> on host 284b5f341ead
[2024-05-05T03:33:54.160+0000] {taskinstance.py:2644} INFO - Exporting env vars: AIRFLOW_CTX_DAG_OWNER='***' AIRFLOW_CTX_DAG_ID='bash' AIRFLOW_CTX_TASK_ID='bash_command' AIRFLOW_CTX_EXECUTION_DATE='2024-05-05T03:33:41.572808+00:00' AIRFLOW_CTX_TRY_NUMBER='1' AIRFLOW_CTX_DAG_RUN_ID='manual__2024-05-05T03:33:41.572808+00:00'
[2024-05-05T03:33:54.162+0000] {taskinstance.py:430} INFO - ::endgroup::
[2024-05-05T03:33:54.178+0000] {subprocess.py:63} INFO - Tmp dir root location: /tmp
[2024-05-05T03:33:54.180+0000] {subprocess.py:75} INFO - Running command: ['/usr/bin/bash', '-c', 'curl -o tmp/xrate.csv "https://data-api.ecb.europa.eu/service/data/EXR/M.USD.EUR.SP00.A?format=csvdata']
[2024-05-05T03:33:54.189+0000] {subprocess.py:86} INFO - Output:
[2024-05-05T03:33:54.191+0000] {subprocess.py:93} INFO - /usr/bin/bash: -c: line 1: unexpected EOF while looking for matching `"'
[2024-05-05T03:33:54.191+0000] {subprocess.py:97} INFO - Command exited with return code 2
[2024-05-05T03:33:54.192+0000] {taskinstance.py:441} INFO - ::group::Post task execution logs
[2024-05-05T03:33:54.202+0000] {taskinstance.py:2890} ERROR - Task failed with exception
Traceback (most recent call last):
  File "/home/airflow/.local/lib/python3.12/site-packages/airflow/models/taskinstance.py", line 465, in _execute_task
    result = _execute_callable(context=context, **execute_callable_kwargs)
             ^^^^^^^^^^^^^^^^^^^^^^^^^^^^^^^^^^^^^^^^^^^^^^^^^^^^^^^^^^^^^
  File "/home/airflow/.local/lib/python3.12/site-packages/airflow/models/taskinstance.py", line 432, in _execute_callable
    return execute_callable(context=context, **execute_callable_kwargs)
           ^^^^^^^^^^^^^^^^^^^^^^^^^^^^^^^^^^^^^^^^^^^^^^^^^^^^^^^^^^^^
  File "/home/airflow/.local/lib/python3.12/site-packages/airflow/models/baseoperator.py", line 400, in wrapper
    return func(self, *args, **kwargs)
           ^^^^^^^^^^^^^^^^^^^^^^^^^^^
  File "/home/airflow/.local/lib/python3.12/site-packages/airflow/operators/bash.py", line 243, in execute
    raise AirflowException(
airflow.exceptions.AirflowException: Bash command failed. The command returned a non-zero exit code 2.
[2024-05-05T03:33:54.208+0000] {taskinstance.py:1205} INFO - Marking task as UP_FOR_RETRY. dag_id=bash, task_id=bash_command, execution_date=20240505T033341, start_date=20240505T033353, end_date=20240505T033354
[2024-05-05T03:33:54.224+0000] {standard_task_runner.py:110} ERROR - Failed to execute job 22 for task bash_command (Bash command failed. The command returned a non-zero exit code 2.; 124)
[2024-05-05T03:33:54.231+0000] {local_task_job_runner.py:240} INFO - Task exited with return code 1
[2024-05-05T03:33:54.248+0000] {taskinstance.py:3482} INFO - 0 downstream tasks scheduled from follow-on schedule check
[2024-05-05T03:33:54.250+0000] {local_task_job_runner.py:222} INFO - ::endgroup::
