[2024-05-05T04:42:16.862+0000] {local_task_job_runner.py:120} INFO - ::group::Pre task execution logs
[2024-05-05T04:42:16.894+0000] {taskinstance.py:2073} INFO - Dependencies all met for dep_context=non-requeueable deps ti=<TaskInstance: mysql_table_dump.mysql_table_dump_task manual__2024-05-05T04:42:15.677691+00:00 [queued]>
[2024-05-05T04:42:16.908+0000] {taskinstance.py:2073} INFO - Dependencies all met for dep_context=requeueable deps ti=<TaskInstance: mysql_table_dump.mysql_table_dump_task manual__2024-05-05T04:42:15.677691+00:00 [queued]>
[2024-05-05T04:42:16.909+0000] {taskinstance.py:2303} INFO - Starting attempt 1 of 2
[2024-05-05T04:42:16.926+0000] {taskinstance.py:2327} INFO - Executing <Task(BashOperator): mysql_table_dump_task> on 2024-05-05 04:42:15.677691+00:00
[2024-05-05T04:42:16.931+0000] {warnings.py:110} WARNING - /home/***/.local/lib/python3.12/site-packages/***/task/task_runner/standard_task_runner.py:61: DeprecationWarning: This process (pid=931) is multi-threaded, use of fork() may lead to deadlocks in the child.
  pid = os.fork()

[2024-05-05T04:42:16.935+0000] {standard_task_runner.py:63} INFO - Started process 932 to run task
[2024-05-05T04:42:16.934+0000] {standard_task_runner.py:90} INFO - Running: ['***', 'tasks', 'run', 'mysql_table_dump', 'mysql_table_dump_task', 'manual__2024-05-05T04:42:15.677691+00:00', '--job-id', '46', '--raw', '--subdir', 'DAGS_FOLDER/dump_load_dag.py', '--cfg-path', '/tmp/tmpcpjvfe3e']
[2024-05-05T04:42:16.937+0000] {standard_task_runner.py:91} INFO - Job 46: Subtask mysql_table_dump_task
[2024-05-05T04:42:17.006+0000] {task_command.py:426} INFO - Running <TaskInstance: mysql_table_dump.mysql_table_dump_task manual__2024-05-05T04:42:15.677691+00:00 [running]> on host 284b5f341ead
[2024-05-05T04:42:17.126+0000] {taskinstance.py:2644} INFO - Exporting env vars: AIRFLOW_CTX_DAG_OWNER='***' AIRFLOW_CTX_DAG_ID='mysql_table_dump' AIRFLOW_CTX_TASK_ID='mysql_table_dump_task' AIRFLOW_CTX_EXECUTION_DATE='2024-05-05T04:42:15.677691+00:00' AIRFLOW_CTX_TRY_NUMBER='1' AIRFLOW_CTX_DAG_RUN_ID='manual__2024-05-05T04:42:15.677691+00:00'
[2024-05-05T04:42:17.127+0000] {taskinstance.py:430} INFO - ::endgroup::
[2024-05-05T04:42:17.151+0000] {subprocess.py:63} INFO - Tmp dir root location: /tmp
[2024-05-05T04:42:17.152+0000] {subprocess.py:75} INFO - Running command: ['/usr/bin/bash', '-c', 'mysqldump -u root -pmysql@123 -h localhost practise customers > /opt/***/dags/dump_file.sql']
[2024-05-05T04:42:17.161+0000] {subprocess.py:86} INFO - Output:
[2024-05-05T04:42:17.170+0000] {subprocess.py:93} INFO - mysqldump: Got error: 2002: "Can't connect to local server through socket '/run/mysqld/mysqld.sock' (2)" when trying to connect
[2024-05-05T04:42:17.171+0000] {subprocess.py:97} INFO - Command exited with return code 2
[2024-05-05T04:42:17.172+0000] {taskinstance.py:441} INFO - ::group::Post task execution logs
[2024-05-05T04:42:17.187+0000] {taskinstance.py:2890} ERROR - Task failed with exception
Traceback (most recent call last):
  File "/home/airflow/.local/lib/python3.12/site-packages/airflow/models/taskinstance.py", line 465, in _execute_task
    result = _execute_callable(context=context, **execute_callable_kwargs)
             ^^^^^^^^^^^^^^^^^^^^^^^^^^^^^^^^^^^^^^^^^^^^^^^^^^^^^^^^^^^^^
  File "/home/airflow/.local/lib/python3.12/site-packages/airflow/models/taskinstance.py", line 432, in _execute_callable
    return execute_callable(context=context, **execute_callable_kwargs)
           ^^^^^^^^^^^^^^^^^^^^^^^^^^^^^^^^^^^^^^^^^^^^^^^^^^^^^^^^^^^^
  File "/home/airflow/.local/lib/python3.12/site-packages/airflow/models/baseoperator.py", line 400, in wrapper
    return func(self, *args, **kwargs)
           ^^^^^^^^^^^^^^^^^^^^^^^^^^^
  File "/home/airflow/.local/lib/python3.12/site-packages/airflow/operators/bash.py", line 243, in execute
    raise AirflowException(
airflow.exceptions.AirflowException: Bash command failed. The command returned a non-zero exit code 2.
[2024-05-05T04:42:17.192+0000] {taskinstance.py:1205} INFO - Marking task as UP_FOR_RETRY. dag_id=mysql_table_dump, task_id=mysql_table_dump_task, execution_date=20240505T044215, start_date=20240505T044216, end_date=20240505T044217
[2024-05-05T04:42:17.208+0000] {standard_task_runner.py:110} ERROR - Failed to execute job 46 for task mysql_table_dump_task (Bash command failed. The command returned a non-zero exit code 2.; 932)
[2024-05-05T04:42:17.230+0000] {local_task_job_runner.py:240} INFO - Task exited with return code 1
[2024-05-05T04:42:17.247+0000] {taskinstance.py:3482} INFO - 0 downstream tasks scheduled from follow-on schedule check
[2024-05-05T04:42:17.250+0000] {local_task_job_runner.py:222} INFO - ::endgroup::
